Workbook

Sheet 生产通知单模版
A1: 生产计划通知单
A2: 区域 | C2: FOB交期 | F2: 尾查期 | J2: 出运方式 | M2: 跟单员 | P2: 制单员 | R2: 制单日期
A3: 订单基本信息 | I3: 生产进度计划 | P3: 重要提示（可多项提示）
A4: 通知单编号 | E4: 面料 | I4: 缝制工厂 | M4: 缝制起始日期
A5: 合同号 | E5: 面料缩率J | M5: 缝制交货日
A6: 分单号(批次) | E6: 面料缩率W | I6: 水洗工厂 | M6: 水洗交货日
A7: 订单号PO | E7: 加裁比例% | I7: 后整工厂 | M7: 后整交货日
A8: 客户/品牌 | E8: 丝带色号 | I8: 审核记录
A9: 款号 | E9: 通知日期 | I9: 计划审批 | M9: 计划审批日期
A10: 品名 | E10: 总数 | I10: 采购审批 | M10: 采购审批日期
A11: 产品分类 | E11: 溢装% | I11: 技术审批 | M11: 技术审批日期
A12: 洗水工艺 | E12: 短装% | I12: 贸易审批 | M12: 贸易审批日期 | P12: 大货洗水流程
A13: 订单数量数量明细 | R13: 总数验证 | T13: =IF(G10=T21,"总数准确","总数错误") -> 总数准确
A14: 国家 | B14: 颜色 | C14: 内长 | D14: 28 | E14: 29 | F14: 30 | G14: 31 | H14: 32 | I14: 33 | J14: 34 | K14: 36 | L14: 38 | M14: 40 | N14: 42 | O14: 44 | T14: 合计
T15: =SUM(D15:S15) -> 0
A21: 小计 | D21: =SUM(D15:D20) -> 0 | E21: =SUM(E15:E20) -> 0 | F21: =SUM(F15:F20) -> 0 | G21: =SUM(G15:G20) -> 0 | H21: =SUM(H15:H20) -> 0 | I21: =SUM(I15:I20) -> 0 | J21: =SUM(J15:J20) -> 0 | K21: =SUM(K15:K20) -> 0 | ... S21: =SUM(S15:S20) -> 0 | T21: =SUM(D21:S21) -> 0
A22: 要求开裁数量明细 | Q22: 加裁比例%（验证用） | T22: =(T30/G10-1)*100 -> #DIV/0!
A23: 国家 | B23: 颜色 | C23: 内长 | D23: =IF(D14="","",D14) -> 28 | E23: =IF(E14="","",E14) -> 29 | F23: =IF(F14="","",F14) -> 30 | G23: =IF(G14="","",G14) -> 31 | H23: =IF(H14="","",H14) -> 32 | I23: =IF(I14="","",I14) -> 33 | J23: =IF(J14="","",J14) -> 34 | K23: =IF(K14="","",K14) -> 36 | ... S23: =IF(S14="","",S14) | T23: 合计
A24: =IF(A15="","",A15) | B24: =IF(B15="","",B15) | C24: =IF(C15="","",C15) | D24: =IF(D15="","",CEILING(D15*(1+$G$7/100),1)) | E24: =IF(E15="","",CEILING(E15*(1+$G$7/100),1)) | F24: =IF(F15="","",CEILING(F15*(1+$G$7/100),1)) | G24: =IF(G15="","",CEILING(G15*(1+$G$7/100),1)) | H24: =IF(H15="","",CEILING(H15*(1+$G$7/100),1)) | I24: =IF(I15="","",CEILING(I15*(1+$G$7/100),1)) | J24: =IF(J15="","",CEILING(J15*(1+$G$7/100),1)) | K24: =IF(K15="","",CEILING(K15*(1+$G$7/100),1)) | ... S24: =IF(S15="","",CEILING(S15*(1+$G$7/100),1)) | T24: =SUM(D24:S24) -> 0
A25: =IF(A16="","",A16) | B25: =IF(B16="","",B16) | C25: =IF(C16="","",C16) | D25: =IF(D16="","",CEILING(D16*(1+$G$7/100),1)) | E25: =IF(E16="","",CEILING(E16*(1+$G$7/100),1)) | F25: =IF(F16="","",CEILING(F16*(1+$G$7/100),1)) | G25: =IF(G16="","",CEILING(G16*(1+$G$7/100),1)) | H25: =IF(H16="","",CEILING(H16*(1+$G$7/100),1)) | I25: =IF(I16="","",CEILING(I16*(1+$G$7/100),1)) | J25: =IF(J16="","",CEILING(J16*(1+$G$7/100),1)) | K25: =IF(K16="","",CEILING(K16*(1+$G$7/100),1)) | ... S25: =IF(S16="","",CEILING(S16*(1+$G$7/100),1))
A26: =IF(A17="","",A17) | B26: =IF(B17="","",B17) | C26: =IF(C17="","",C17) | D26: =IF(D17="","",CEILING(D17*(1+$G$7/100),1)) | E26: =IF(E17="","",CEILING(E17*(1+$G$7/100),1)) | F26: =IF(F17="","",CEILING(F17*(1+$G$7/100),1)) | G26: =IF(G17="","",CEILING(G17*(1+$G$7/100),1)) | H26: =IF(H17="","",CEILING(H17*(1+$G$7/100),1)) | I26: =IF(I17="","",CEILING(I17*(1+$G$7/100),1)) | J26: =IF(J17="","",CEILING(J17*(1+$G$7/100),1)) | L26: =IF(L17="","",CEILING(L17*(1+$G$7/100),1)) | M26: =IF(M17="","",CEILING(M17*(1+$G$7/100),1)) | N26: =IF(N17="","",CEILING(N17*(1+$G$7/100),1)) | O26: =IF(O17="","",CEILING(O17*(1+$G$7/100),1)) | P26: =IF(P17="","",CEILING(P17*(1+$G$7/100),1)) | Q26: =IF(Q17="","",CEILING(Q17*(1+$G$7/100),1)) | R26: =IF(R17="","",CEILING(R17*(1+$G$7/100),1)) | S26: =IF(S17="","",CEILING(S17*(1+$G$7/100),1))
A27: =IF(A18="","",A18) | B27: =IF(B18="","",B18) | C27: =IF(C18="","",C18) | D27: =IF(D18="","",CEILING(D18*(1+$G$7/100),1)) | E27: =IF(E18="","",CEILING(E18*(1+$G$7/100),1)) | F27: =IF(F18="","",CEILING(F18*(1+$G$7/100),1)) | G27: =IF(G18="","",CEILING(G18*(1+$G$7/100),1)) | H27: =IF(H18="","",CEILING(H18*(1+$G$7/100),1)) | I27: =IF(I18="","",CEILING(I18*(1+$G$7/100),1)) | J27: =IF(J18="","",CEILING(J18*(1+$G$7/100),1)) | K27: =IF(K18="","",CEILING(K18*(1+$G$7/100),1)) | ... S27: =IF(S18="","",CEILING(S18*(1+$G$7/100),1))
A28: =IF(A19="","",A19) | B28: =IF(B19="","",B19) | C28: =IF(C19="","",C19) | D28: =IF(D19="","",CEILING(D19*(1+$G$7/100),1)) | E28: =IF(E19="","",CEILING(E19*(1+$G$7/100),1)) | F28: =IF(F19="","",CEILING(F19*(1+$G$7/100),1)) | G28: =IF(G19="","",CEILING(G19*(1+$G$7/100),1)) | H28: =IF(H19="","",CEILING(H19*(1+$G$7/100),1)) | I28: =IF(I19="","",CEILING(I19*(1+$G$7/100),1)) | J28: =IF(J19="","",CEILING(J19*(1+$G$7/100),1)) | K28: =IF(K19="","",CEILING(K19*(1+$G$7/100),1)) | ... S28: =IF(S19="","",CEILING(S19*(1+$G$7/100),1))
A29: =IF(A20="","",A20) | B29: =IF(B20="","",B20) | C29: =IF(C20="","",C20) | D29: =IF(D20="","",CEILING(D20*(1+$G$7/100),1)) | E29: =IF(E20="","",CEILING(E20*(1+$G$7/100),1)) | F29: =IF(F20="","",CEILING(F20*(1+$G$7/100),1)) | G29: =IF(G20="","",CEILING(G20*(1+$G$7/100),1)) | H29: =IF(H20="","",CEILING(H20*(1+$G$7/100),1)) | I29: =IF(I20="","",CEILING(I20*(1+$G$7/100),1)) | J29: =IF(J20="","",CEILING(J20*(1+$G$7/100),1)) | K29: =IF(K20="","",CEILING(K20*(1+$G$7/100),1)) | ... S29: =IF(S20="","",CEILING(S20*(1+$G$7/100),1)) | T29: 0
A30: 小计 | D30: =SUM(D24:D29) -> 0 | E30: =SUM(E24:E29) -> 0 | F30: =SUM(F24:F29) -> 0 | G30: =SUM(G24:G29) -> 0 | H30: =SUM(H24:H29) -> 0 | I30: =SUM(I24:I29) -> 0 | J30: =SUM(J24:J29) -> 0 | K30: =SUM(K24:K29) -> 0 | ... S30: =SUM(S24:S29) -> 0 | T30: =SUM(D30:S30) -> 0
A32: 物料定额计划表
A33: 原材料分类 | B33: 物料名称 | C33: 规格 | E33: 颜色/代码 | F33: 单位 | G33: 单耗 | H33: 采购数量 | I33: 单价 | J33: 小计 | K33: 实际单耗 | L33: 备注 | O33: 供应商 | P33: 下订日期 | Q33: 订购人 | R33: 预定交期 | S33: 实际进仓到货期 | T33: 仓库确认实收数量
H34: =+T$30*G34 -> 0 | I34: =IF(B34="","",VLOOKUP(B34,[1]常用辅料信息表!$D$1:$H$65536,4,FALSE)) | J34: =IF(I34="","",H34*I34) | O34: =IF(B34="","",VLOOKUP(B34,[1]常用辅料信息表!$D$1:$H$65536,5,FALSE))
H35: =+T$30*G35 -> 0 | I35: =IF(B35="","",VLOOKUP(B35,[1]常用辅料信息表!$D$1:$H$65536,4,FALSE)) | J35: =IF(I35="","",H35*I35) | O35: =IF(B35="","",VLOOKUP(B35,[1]常用辅料信息表!$D$1:$H$65536,5,FALSE))
H36: =+T$30*G36 -> 0 | I36: =IF(B36="","",VLOOKUP(B36,[1]常用辅料信息表!$D$1:$H$65536,4,FALSE)) | J36: =IF(I36="","",H36*I36) | O36: =IF(B36="","",VLOOKUP(B36,[1]常用辅料信息表!$D$1:$H$65536,5,FALSE))
H37: =+T$30*G37 -> 0 | J37: =IF(I37="","",H37*I37) | O37: =IF(B37="","",VLOOKUP(B37,[1]常用辅料信息表!$D$1:$H$65536,5,FALSE))
H38: =+T$30*G38 -> 0 | J38: =IF(I38="","",H38*I38) | O38: =IF(B38="","",VLOOKUP(B38,[1]常用辅料信息表!$D$1:$H$65536,5,FALSE))
H39: =+T$30*G39 -> 0 | I39: =IF(B39="","",VLOOKUP(B39,[1]常用辅料信息表!$D$1:$H$65536,4,FALSE)) | J39: =IF(I39="","",H39*I39) | O39: =IF(B39="","",VLOOKUP(B39,[1]常用辅料信息表!$D$1:$H$65536,5,FALSE))
H40: =+T$30*G40 -> 0 | I40: =IF(B40="","",VLOOKUP(B40,[1]常用辅料信息表!$D$1:$H$65536,4,FALSE)) | J40: =IF(I40="","",H40*I40) | O40: =IF(B40="","",VLOOKUP(B40,[1]常用辅料信息表!$D$1:$H$65536,5,FALSE))
H41: =+T$30*G41 -> 0 | I41: =IF(B41="","",VLOOKUP(B41,[1]常用辅料信息表!$D$1:$H$65536,4,FALSE)) | J41: =IF(I41="","",H41*I41) | O41: =IF(B41="","",VLOOKUP(B41,[1]常用辅料信息表!$D$1:$H$65536,5,FALSE))
H42: =+T$30*G42 -> 0 | I42: =IF(B42="","",VLOOKUP(B42,[1]常用辅料信息表!$D$1:$H$65536,4,FALSE)) | J42: =IF(I42="","",H42*I42) | O42: =IF(B42="","",VLOOKUP(B42,[1]常用辅料信息表!$D$1:$H$65536,5,FALSE))
H43: =+T$30*G43 -> 0 | I43: =IF(B43="","",VLOOKUP(B43,[1]常用辅料信息表!$D$1:$H$65536,4,FALSE)) | J43: =IF(I43="","",H43*I43) | O43: =IF(B43="","",VLOOKUP(B43,[1]常用辅料信息表!$D$1:$H$65536,5,FALSE))
H44: =+T$30*G44 -> 0 | I44: =IF(B44="","",VLOOKUP(B44,[1]常用辅料信息表!$D$1:$H$65536,4,FALSE)) | J44: =IF(I44="","",H44*I44) | O44: =IF(B44="","",VLOOKUP(B44,[1]常用辅料信息表!$D$1:$H$65536,5,FALSE))
H45: =+T$30*G45 -> 0
H46: =+T$30*G46 -> 0 | I46: =IF(B46="","",VLOOKUP(B46,[1]常用辅料信息表!$D$1:$H$65536,4,FALSE)) | J46: =IF(I46="","",H46*I46) | O46: =IF(B46="","",VLOOKUP(B46,[1]常用辅料信息表!$D$1:$H$65536,5,FALSE))
...

Sheet 常用辅料信息表
A1: 定价日期 | B1: 客户 | C1: 原料分类 | D1: 辅料分类 | E1: 辅料编号 | F1: 规格 | G1: 单价 | H1: 常用供应商 | I1: 定价员
A2: 40964 | B2: HM | C2: 缝纫线 | D2: 缝纫线 | E2: TEX90/203 | F2: 1500 | G2: 1 | H2: A1
A3: 40964 | B3: HM | C3: 缝纫线 | D3: 缝纫线 | E3: TEX60/202 | F3: 3000 | G3: 2 | H3: A1
A4: 40964 | B4: HM | C4: 缝纫线 | D4: 缝纫线 | E4: 403 | F4: 3000 | G4: 1 | H4: A1
A5: 40964 | B5: HM | C5: 缝纫线 | D5: 缝纫线 | E5: 302 | F5: 3000 | G5: 1 | H5: A1
A6: 40964 | B6: HM | C6: 缝纫线 | D6: 缝纫线 | E6: 209 | F6: 500 | G6: 1 | H6: A1
A7: 40964 | B7: HM | C7: 缝纫线 | D7: 缝纫线 | E7: 202 | F7: 3000 | G7: 1 | H7: A1
A8: 40964 | B8: HM | C8: 缝纫线 | D8: 缝纫线 | E8: 163 | F8: 1500 | G8: 1 | H8: A1
A9: 40964 | B9: HM | C9: 主面料 | D9: 面料 | E9: 09-090 | G9: 10 | H9: M1
A10: 40964 | B10: HM | C10: 配料 | D10: 袋布+加强布 | E10: 门幅-57 | G10: 9.9 | H10: M23
A11: 40964 | B11: HM | C11: 配料 | D11: 有纺衬 | E11: 门幅-150CM | G11: 9.8 | H11: M23
A12: 40964 | B12: HM | C12: 前道辅料 | D12: 主标 | E12: HM18009 | G12: 9.7 | H12: F25
A13: 40964 | B13: HM | C13: 前道辅料 | D13: 尺码标 | E13: HM22035 | G13: 9.6 | H13: F25
A14: 40964 | B14: HM | C14: 前道辅料 | D14: 洗标 | E14: HM30000 | G14: 9.5 | H14: F25
A15: 40964 | B15: HM | C15: 前道辅料 | D15: 门巾拉链 | E15: YKK580 | G15: 9.4 | H15: F28
A16: 40964 | B16: HM | C16: 前道辅料 | D16: PP小胶袋 | E16: 8*5CM | G16: 9.3 | H16: F10
A17: 40964 | B17: HM | C17: 前道辅料 | D17: PP小胶袋 | E17: 6*5CM | G17: 9.2 | H17: F10
A18: 40964 | B18: HM | C18: 后道辅料 | D18: 工字扣 | E18: 27L | G18: 9.1 | H18: F26
A19: 40964 | B19: HM | C19: 后道辅料 | D19: 价格牌 | E19: HM01 | G19: 9 | H19: F26
A20: 40964 | B20: HM | C20: 后道辅料 | D20: 枪针 | E20: 1″ | G20: 8.9 | H20: F10
... A22: 40964 | B22: HM | C22: 装箱辅料 | D22: 箱唛 | E22: PE-HD 02 | G22: 8.6 | H22: F30
A23: 40964 | B23: HM | C23: 装箱辅料 | D23: 箱袋 | G23: 8.5 | H23: F30
A24: 40964 | B24: HM | C24: 装箱辅料 | D24: 纸箱 | G24: 8.4 | H24: F30
A25: 40964 | B25: HM | C25: 装箱辅料 | D25: 封箱带 | G25: 8.3 | H25: F30

Sheet Sheet3
